Workbook
Name Slicer_Diabetes_Status: #N/A
Name Slicer_Weight_Status: #N/A

Sheet Customer Names
A1: Customer ID | B1: name | C1: Title | D1: First Name | E1: Last Name | F1: Title using formula
A2: Id1 | B2: Hawks, Ms. Kelly | C2: Ms. | D2: Kelly | E2: Hawks | G2: =TRIM(MID(B2,FIND(",",B2)+1,4)) -> Ms.
A3: Id2 | B3: Lehner, Mr. Matthew D | C3: Mr. | D3: Matthew D | E3: Lehner | G3: =TRIM(MID(B3,FIND(",",B3)+1,4)) -> Mr.
A4: Id3 | B4: Lu, Mr. Phil | C4: Mr. | D4: Phil | E4: Lu | G4: =TRIM(MID(B4,FIND(",",B4)+1,4)) -> Mr.
A5: Id4 | B5: Osborne, Ms. Kelsey | C5: Ms. | D5: Kelsey | E5: Osborne | G5: =TRIM(MID(B5,FIND(",",B5)+1,4)) -> Ms.
A6: Id5 | B6: Kadala, Ms. Kristyn | C6: Ms. | D6: Kristyn | E6: Kadala | G6: =TRIM(MID(B6,FIND(",",B6)+1,4)) -> Ms.
A7: Id6 | B7: Baker, Mr. Russell B. | C7: Mr. | D7: Russell B. | E7: Baker | G7: =TRIM(MID(B7,FIND(",",B7)+1,4)) -> Mr.
A8: Id7 | B8: Macpherson, Mr. Scott | C8: Mr. | D8: Scott | E8: Macpherson | G8: =TRIM(MID(B8,FIND(",",B8)+1,4)) -> Mr.
A9: Id8 | B9: Hallman, Mr. Stephen | C9: Mr. | D9: Stephen | E9: Hallman | G9: =TRIM(MID(B9,FIND(",",B9)+1,4)) -> Mr.
A10: Id9 | B10: Moran, Mr. Patrick R. | C10: Mr. | D10: Patrick R. | E10: Moran | G10: =TRIM(MID(B10,FIND(",",B10)+1,4)) -> Mr.
A11: Id10 | B11: Benner, Ms. Brooke N. | C11: Ms. | D11: Brooke N. | E11: Benner | G11: =TRIM(MID(B11,FIND(",",B11)+1,4)) -> Ms.
A12: Id11 | B12: Fierro Vargas, Ms. Paola Andrea | C12: Ms. | D12: Paola Andrea | E12: Fierro Vargas | G12: =TRIM(MID(B12,FIND(",",B12)+1,4)) -> Ms.
A13: Id12 | B13: Franz, Mr. David | C13: Mr. | D13: David | E13: Franz | G13: =TRIM(MID(B13,FIND(",",B13)+1,4)) -> Mr.
... A2336: Id2335 | B2336: German, Mr. Aaron K | C2336: Mr. | D2336: Aaron K | E2336: German | G2336: =TRIM(MID(B2336,FIND(",",B2336)+1,4)) -> Mr.

Sheet Medical Examinations
A1: Customer ID | B1: BMI | C1: HBA1C | D1: Heart Issues | E1: Any Transplants | F1: Cancer history | G1: NumberOfMajorSurgeries | H1: smoker | I1: Weight Status | J1: Diabetes Status
A2: Id1 | B2: 47.41 | C2: 7.47 | D2: No | E2: No | F2: No | G2: 0 | H2: Yes | I2: {=_xlfn.IFS(B2<18.5,"Underweight",B2<25,"Normal Weight",B2<30,"Overweight",B2>=30,"Obesity")} -> Obesity | J2: {=_xlfn.IFS(C2<5.7,"Normal",C2<6.5,"Prediabetes",C2>=6.5,"Diabetes")} -> Diabetes | S2: Mode of Smoker
A3: Id2 | B3: 30.36 | C3: 5.77 | D3: No | E3: No | F3: No | G3: 0 | H3: Yes | I3: {=_xlfn.IFS(B3<18.5,"Underweight",B3<25,"Normal Weight",B3<30,"Overweight",B3>=30,"Obesity")} -> Obesity | J3: {=_xlfn.IFS(C3<5.7,"Normal",C3<6.5,"Prediabetes",C3>=6.5,"Diabetes")} -> Prediabetes
A4: Id3 | B4: 34.485 | C4: 11.87 | D4: Yes | E4: No | F4: No | G4: 2 | H4: Yes | I4: {=_xlfn.IFS(B4<18.5,"Underweight",B4<25,"Normal Weight",B4<30,"Overweight",B4>=30,"Obesity")} -> Obesity | J4: {=_xlfn.IFS(C4<5.7,"Normal",C4<6.5,"Prediabetes",C4>=6.5,"Diabetes")} -> Diabetes | S4: Yes | T4: =COUNTIF(H2:H2336,H2) -> 488
A5: Id4 | B5: 38.095 | C5: 6.05 | D5: No | E5: No | F5: No | G5: 0 | H5: Yes | I5: {=_xlfn.IFS(B5<18.5,"Underweight",B5<25,"Normal Weight",B5<30,"Overweight",B5>=30,"Obesity")} -> Obesity | J5: {=_xlfn.IFS(C5<5.7,"Normal",C5<6.5,"Prediabetes",C5>=6.5,"Diabetes")} -> Prediabetes | S5: No | T5: =COUNTIF(H2:H2336,H2321) -> 1847
A6: Id5 | B6: 35.53 | C6: 5.45 | D6: No | E6: No | F6: No | G6: 0 | H6: Yes | I6: {=_xlfn.IFS(B6<18.5,"Underweight",B6<25,"Normal Weight",B6<30,"Overweight",B6>=30,"Obesity")} -> Obesity | J6: {=_xlfn.IFS(C6<5.7,"Normal",C6<6.5,"Prediabetes",C6>=6.5,"Diabetes")} -> Normal | S6: ? | T6: =COUNTIF(H2:H2336,"?") -> 0
A7: Id6 | B7: 32.8 | C7: 6.59 | D7: No | E7: No | F7: No | G7: 0 | H7: Yes | I7: {=_xlfn.IFS(B7<18.5,"Underweight",B7<25,"Normal Weight",B7<30,"Overweight",B7>=30,"Obesity")} -> Obesity | J7: {=_xlfn.IFS(C7<5.7,"Normal",C7<6.5,"Prediabetes",C7>=6.5,"Diabetes")} -> Diabetes | S7: There for the most repeated value of smoker is No.
A8: Id7 | B8: 36.4 | C8: 6.07 | D8: No | E8: No | F8: No | G8: 0 | H8: Yes | I8: {=_xlfn.IFS(B8<18.5,"Underweight",B8<25,"Normal Weight",B8<30,"Overweight",B8>=30,"Obesity")} -> Obesity | J8: {=_xlfn.IFS(C8<5.7,"Normal",C8<6.5,"Prediabetes",C8>=6.5,"Diabetes")} -> Prediabetes
A9: Id8 | B9: 36.96 | C9: 7.93 | D9: No | E9: No | F9: No | G9: 3 | H9: Yes | I9: {=_xlfn.IFS(B9<18.5,"Underweight",B9<25,"Normal Weight",B9<30,"Overweight",B9>=30,"Obesity")} -> Obesity | J9: {=_xlfn.IFS(C9<5.7,"Normal",C9<6.5,"Prediabetes",C9>=6.5,"Diabetes")} -> Diabetes
A10: Id9 | B10: 41.14 | C10: 9.58 | D10: Yes | E10: No | F10: Yes | G10: 1 | H10: Yes | I10: {=_xlfn.IFS(B10<18.5,"Underweight",B10<25,"Normal Weight",B10<30,"Overweight",B10>=30,"Obesity")} -> Obesity | J10: {=_xlfn.IFS(C10<5.7,"Normal",C10<6.5,"Prediabetes",C10>=6.5,"Diabetes")} -> Diabetes
A11: Id10 | B11: 38.06 | C11: 10.79 | D11: No | E11: No | F11: No | G11: 0 | H11: Yes | I11: {=_xlfn.IFS(B11<18.5,"Underweight",B11<25,"Normal Weight",B11<30,"Overweight",B11>=30,"Obesity")} -> Obesity | J11: {=_xlfn.IFS(C11<5.7,"Normal",C11<6.5,"Prediabetes",C11>=6.5,"Diabetes")} -> Diabetes
A12: Id11 | B12: 37.7 | C12: 5.96 | D12: Yes | E12: No | F12: No | G12: 2 | H12: Yes | I12: {=_xlfn.IFS(B12<18.5,"Underweight",B12<25,"Normal Weight",B12<30,"Overweight",B12>=30,"Obesity")} -> Obesity | J12: {=_xlfn.IFS(C12<5.7,"Normal",C12<6.5,"Prediabetes",C12>=6.5,"Diabetes")} -> Prediabetes
A13: Id12 | B13: 42.13 | C13: 11.9 | D13: No | E13: No | F13: No | G13: 0 | H13: Yes | I13: {=_xlfn.IFS(B13<18.5,"Underweight",B13<25,"Normal Weight",B13<30,"Overweight",B13>=30,"Obesity")} -> Obesity | J13: {=_xlfn.IFS(C13<5.7,"Normal",C13<6.5,"Prediabetes",C13>=6.5,"Diabetes")} -> Diabetes
A14: Id13 | B14: 40.92 | C14: 8.41 | D14: No | E14: No | F14: No | G14: 0 | H14: Yes | I14: {=_xlfn.IFS(B14<18.5,"Underweight",B14<25,"Normal Weight",B14<30,"Overweight",B14>=30,"Obesity")} -> Obesity | J14: {=_xlfn.IFS(C14<5.7,"Normal",C14<6.5,"Prediabetes",C14>=6.5,"Diabetes")} -> Diabetes
A15: Id14 | B15: 40.565 | C15: 7.02 | D15: No | E15: No | F15: No | G15: 0 | H15: Yes | I15: {=_xlfn.IFS(B15<18.5,"Underweight",B15<25,"Normal Weight",B15<30,"Overweight",B15>=30,"Obesity")} -> Obesity | J15: {=_xlfn.IFS(C15<5.7,"Normal",C15<6.5,"Prediabetes",C15>=6.5,"Diabetes")} -> Diabetes | S15: NumberOfMajorSurgeries Count
A16: Id15 | B16: 36.385 | C16: 7.59 | D16: Yes | E16: No | F16: No | G16: 2 | H16: Yes | I16: {=_xlfn.IFS(B16<18.5,"Underweight",B16<25,"Normal Weight",B16<30,"Overweight",B16>=30,"Obesity")} -> Obesity | J16: {=_xlfn.IFS(C16<5.7,"Normal",C16<6.5,"Prediabetes",C16>=6.5,"Diabetes")} -> Diabetes | S16: 0 | T16: =COUNTIF(G2:G2336,G2246) -> 1074
A17: Id16 | B17: 39.9 | C17: 11.32 | D17: No | E17: No | F17: No | G17: 0 | H17: Yes | I17: {=_xlfn.IFS(B17<18.5,"Underweight",B17<25,"Normal Weight",B17<30,"Overweight",B17>=30,"Obesity")} -> Obesity | J17: {=_xlfn.IFS(C17<5.7,"Normal",C17<6.5,"Prediabetes",C17>=6.5,"Diabetes")} -> Diabetes | S17: 1 | T17: =COUNTIF(G2:G2336,G2332) -> 965
A18: Id17 | B18: 33.8 | C18: 7.67 | D18: No | E18: No | F18: No | G18: 3 | H18: Yes | I18: {=_xlfn.IFS(B18<18.5,"Underweight",B18<25,"Normal Weight",B18<30,"Overweight",B18>=30,"Obesity")} -> Obesity | J18: {=_xlfn.IFS(C18<5.7,"Normal",C18<6.5,"Prediabetes",C18>=6.5,"Diabetes")} -> Diabetes | S18: 2 | T18: =COUNTIF(G2:G2336,G4) -> 274
A19: Id18 | B19: 36.765 | C19: 7.29 | D19: Yes | E19: No | F19: Yes | G19: 1 | H19: Yes | I19: {=_xlfn.IFS(B19<18.5,"Underweight",B19<25,"Normal Weight",B19<30,"Overweight",B19>=30,"Obesity")} -> Obesity | J19: {=_xlfn.IFS(C19<5.7,"Normal",C19<6.5,"Prediabetes",C19>=6.5,"Diabetes")} -> Diabetes | S19: 3 | T19: =COUNTIF(G2:G2336,G9) -> 22
A20: Id19 | B20: 36.955 | C20: 4.72 | D20: Yes | E20: No | F20: No | G20: 1 | H20: Yes | I20: {=_xlfn.IFS(B20<18.5,"Underweight",B20<25,"Normal Weight",B20<30,"Overweight",B20>=30,"Obesity")} -> Obesity | J20: {=_xlfn.IFS(C20<5.7,"Normal",C20<6.5,"Prediabetes",C20>=6.5,"Diabetes")} -> Normal
A21: Id20 | B21: 42.9 | C21: 11.41 | D21: No | E21: No | F21: No | G21: 0 | H21: Yes | I21: {=_xlfn.IFS(B21<18.5,"Underweight",B21<25,"Normal Weight",B21<30,"Overweight",B21>=30,"Obesity")} -> Obesity | J21: {=_xlfn.IFS(C21<5.7,"Normal",C21<6.5,"Prediabetes",C21>=6.5,"Diabetes")} -> Diabetes
A22: Id21 | B22: 36.3 | C22: 11.5 | D22: Yes | E22: No | F22: No | G22: 2 | H22: Yes | I22: {=_xlfn.IFS(B22<18.5,"Underweight",B22<25,"Normal Weight",B22<30,"Overweight",B22>=30,"Obesity")} -> Obesity | J22: {=_xlfn.IFS(C22<5.7,"Normal",C22<6.5,"Prediabetes",C22>=6.5,"Diabetes")} -> Diabetes | S22: Inconsistencies in Heart Issues
A23: Id22 | B23: 32.2 | C23: 6.22 | D23: Yes | E23: No | F23: No | G23: 2 | H23: Yes | I23: {=_xlfn.IFS(B23<18.5,"Underweight",B23<25,"Normal Weight",B23<30,"Overweight",B23>=30,"Obesity")} -> Obesity | J23: {=_xlfn.IFS(C23<5.7,"Normal",C23<6.5,"Prediabetes",C23>=6.5,"Diabetes")} -> Prediabetes
A24: Id23 | B24: 31.3 | C24: 11.38 | D24: No | E24: No | F24: No | G24: 3 | H24: Yes | I24: {=_xlfn.IFS(B24<18.5,"Underweight",B24<25,"Normal Weight",B24<30,"Overweight",B24>=30,"Obesity")} -> Obesity | J24: {=_xlfn.IFS(C24<5.7,"Normal",C24<6.5,"Prediabetes",C24>=6.5,"Diabetes")} -> Diabetes | S24: Yes | T24: =COUNTIF(D2:D2336,D2236) -> 926
A25: Id24 | B25: 41.8 | C25: 7.89 | D25: Yes | E25: No | F25: No | G25: 2 | H25: Yes | I25: {=_xlfn.IFS(B25<18.5,"Underweight",B25<25,"Normal Weight",B25<30,"Overweight",B25>=30,"Obesity")} -> Obesity | J25: {=_xlfn.IFS(C25<5.7,"Normal",C25<6.5,"Prediabetes",C25>=6.5,"Diabetes")} -> Diabetes | S25: No | T25: =COUNTIF(D2:D2336,D2317) -> 1409
A26: Id25 | B26: 35.09 | C26: 4.38 | D26: Yes | E26: No | F26: No | G26: 2 | H26: Yes | I26: {=_xlfn.IFS(B26<18.5,"Underweight",B26<25,"Normal Weight",B26<30,"Overweight",B26>=30,"Obesity")} -> Obesity | J26: {=_xlfn.IFS(C26<5.7,"Normal",C26<6.5,"Prediabetes",C26>=6.5,"Diabetes")} -> Normal | S26: ? | T26: =COUNTIF(D2:D2362,"?") -> 0
A27: Id26 | B27: 33.88 | C27: 7.01 | D27: No | E27: No | F27: No | G27: 3 | H27: Yes | I27: {=_xlfn.IFS(B27<18.5,"Underweight",B27<25,"Normal Weight",B27<30,"Overweight",B27>=30,"Obesity")} -> Obesity | J27: {=_xlfn.IFS(C27<5.7,"Normal",C27<6.5,"Prediabetes",C27>=6.5,"Diabetes")} -> Diabetes | S27: There are no Inconsistencies in Heart Issue column.
A28: Id27 | B28: 30.875 | C28: 11.88 | D28: No | E28: No | F28: No | G28: 0 | H28: Yes | I28: {=_xlfn.IFS(B28<18.5,"Underweight",B28<25,"Normal Weight",B28<30,"Overweight",B28>=30,"Obesity")} -> Obesity | J28: {=_xlfn.IFS(C28<5.7,"Normal",C28<6.5,"Prediabetes",C28>=6.5,"Diabetes")} -> Diabetes | S28: After replacing with a proper consistencie.
A29: Id28 | B29: 36.86 | C29: 5.19 | D29: Yes | E29: No | F29: Yes | G29: 1 | H29: Yes | I29: {=_xlfn.IFS(B29<18.5,"Underweight",B29<25,"Normal Weight",B29<30,"Overweight",B29>=30,"Obesity")} -> Obesity | J29: {=_xlfn.IFS(C29<5.7,"Normal",C29<6.5,"Prediabetes",C29>=6.5,"Diabetes")} -> Normal
A30: Id29 | B30: 35.86 | C30: 6.74 | D30: Yes | E30: No | F30: No | G30: 2 | H30: Yes | I30: {=_xlfn.IFS(B30<18.5,"Underweight",B30<25,"Normal Weight",B30<30,"Overweight",B30>=30,"Obesity")} -> Obesity | J30: {=_xlfn.IFS(C30<5.7,"Normal",C30<6.5,"Prediabetes",C30>=6.5,"Diabetes")} -> Diabetes | S30: Inconsistencies in Smoker
A31: Id30 | B31: 37.05 | C31: 8.44 | D31: No | E31: No | F31: No | G31: 0 | H31: Yes | I31: {=_xlfn.IFS(B31<18.5,"Underweight",B31<25,"Normal Weight",B31<30,"Overweight",B31>=30,"Obesity")} -> Obesity | J31: {=_xlfn.IFS(C31<5.7,"Normal",C31<6.5,"Prediabetes",C31>=6.5,"Diabetes")} -> Diabetes
A32: Id31 | B32: 43.89 | C32: 8.71 | D32: No | E32: No | F32: No | G32: 0 | H32: Yes | I32: {=_xlfn.IFS(B32<18.5,"Underweight",B32<25,"Normal Weight",B32<30,"Overweight",B32>=30,"Obesity")} -> Obesity | J32: {=_xlfn.IFS(C32<5.7,"Normal",C32<6.5,"Prediabetes",C32>=6.5,"Diabetes")} -> Diabetes | S32: Yes | T32: =COUNTIF(H2:H2336,H83) -> 488
A33: Id32 | B33: 42.35 | C33: 5.08 | D33: Yes | E33: No | F33: No | G33: 0 | H33: Yes | I33: {=_xlfn.IFS(B33<18.5,"Underweight",B33<25,"Normal Weight",B33<30,"Overweight",B33>=30,"Obesity")} -> Obesity | J33: {=_xlfn.IFS(C33<5.7,"Normal",C33<6.5,"Prediabetes",C33>=6.5,"Diabetes")} -> Normal | S33: No | T33: =COUNTIF(H2:H2336,H2317) -> 1847
A34: Id33 | B34: 31.35 | C34: 6.86 | D34: No | E34: No | F34: No | G34: 0 | H34: Yes | I34: {=_xlfn.IFS(B34<18.5,"Underweight",B34<25,"Normal Weight",B34<30,"Overweight",B34>=30,"Obesity")} -> Obesity | J34: {=_xlfn.IFS(C34<5.7,"Normal",C34<6.5,"Prediabetes",C34>=6.5,"Diabetes")} -> Diabetes | S34: ? | T34: =COUNTIF(H2:H2371,"?") -> 0
A35: Id34 | B35: 47.6 | C35: 5.95 | D35: Yes | E35: No | F35: No | G35: 0 | H35: Yes | I35: {=_xlfn.IFS(B35<18.5,"Underweight",B35<25,"Normal Weight",B35<30,"Overweight",B35>=30,"Obesity")} -> Obesity | J35: {=_xlfn.IFS(C35<5.7,"Normal",C35<6.5,"Prediabetes",C35>=6.5,"Diabetes")} -> Prediabetes | S35: There are no remaining inconsistencies in the smoker column.
A36: Id35 | B36: 46.2 | C36: 6.09 | D36: No | E36: No | F36: Yes | G36: 1 | H36: Yes | I36: {=_xlfn.IFS(B36<18.5,"Underweight",B36<25,"Normal Weight",B36<30,"Overweight",B36>=30,"Obesity")} -> Obesity | J36: {=_xlfn.IFS(C36<5.7,"Normal",C36<6.5,"Prediabetes",C36>=6.5,"Diabetes")} -> Prediabetes | S36: The missing ? values were handled during Data Cleaning by replacing
A37: Id36 | B37: 32.015 | C37: 11.75 | D37: No | E37: No | F37: No | G37: 0 | H37: Yes | I37: {=_xlfn.IFS(B37<18.5,"Underweight",B37<25,"Normal Weight",B37<30,"Overweight",B37>=30,"Obesity")} -> Obesity | J37: {=_xlfn.IFS(C37<5.7,"Normal",C37<6.5,"Prediabetes",C37>=6.5,"Diabetes")} -> Diabetes | S37: them with the most frequently occurring value, No.
A38: Id37 | B38: 40.565 | C38: 7.37 | D38: No | E38: No | F38: No | G38: 0 | H38: Yes | I38: {=_xlfn.IFS(B38<18.5,"Underweight",B38<25,"Normal Weight",B38<30,"Overweight",B38>=30,"Obesity")} -> Obesity | J38: {=_xlfn.IFS(C38<5.7,"Normal",C38<6.5,"Prediabetes",C38>=6.5,"Diabetes")} -> Diabetes
A39: Id38 | B39: 32.45 | C39: 11.91 | D39: No | E39: No | F39: No | G39: 0 | H39: Yes | I39: {=_xlfn.IFS(B39<18.5,"Underweight",B39<25,"Normal Weight",B39<30,"Overweight",B39>=30,"Obesity")} -> Obesity | J39: {=_xlfn.IFS(C39<5.7,"Normal",C39<6.5,"Prediabetes",C39>=6.5,"Diabetes")} -> Diabetes
A40: Id39 | B40: 34.96 | C40: 6.52 | D40: No | E40: No | F40: No | G40: 0 | H40: Yes | I40: {=_xlfn.IFS(B40<18.5,"Underweight",B40<25,"Normal Weight",B40<30,"Overweight",B40>=30,"Obesity")} -> Obesity | J40: {=_xlfn.IFS(C40<5.7,"Normal",C40<6.5,"Prediabetes",C40>=6.5,"Diabetes")} -> Diabetes
...

Sheet Hospitalisation Details
A1: Customer ID | B1: year | C1: month | D1: date | E1: children | F1: charges | G1: Hospital tier | H1: City tier | I1: State ID | J1: Date of Birth | K1: Age
A2: ? | B2: 2004 | C2: Nov | D2: 6 | E2: 0 | F2: 1137.01 | G2: tier - 3 | H2: tier - 1 | I2: R1013 | J2: =D2&"-"&C2&"-"&B2 -> 6-Nov-2004 | K2: =DATEDIF(J2,DATE(2023,6,8),"Y") -> 18
A3: ? | B3: 1999 | C3: Jun | D3: 9 | E3: 1 | F3: 2775.19 | G3: tier - 2 | H3: tier - 1 | I3: R1012 | J3: =D3&"-"&C3&"-"&B3 -> 9-Jun-1999 | K3: =DATEDIF(J3,DATE(2023,6,8),"Y") -> 23
A4: ? | B4: 1985 | C4: Dec | D4: 20 | E4: 2 | F4: 6203.9 | G4: tier - 1 | H4: tier - 2 | I4: R1012 | J4: =D4&"-"&C4&"-"&B4 -> 20-Dec-1985 | K4: =DATEDIF(J4,DATE(2023,6,8),"Y") -> 37
A5: ? | B5: 2000 | C5: Oct | D5: 13 | E5: 0 | F5: 35585.58 | G5: tier - 1 | H5: tier - 2 | I5: R1011 | J5: =D5&"-"&C5&"-"&B5 -> 13-Oct-2000 | K5: =DATEDIF(J5,DATE(2023,6,8),"Y") -> 22
A6: ? | B6: 1992 | C6: Oct | D6: 6 | E6: 0 | F6: 36837.47 | G6: tier - 1 | H6: tier - 2 | I6: R1011 | J6: =D6&"-"&C6&"-"&B6 -> 6-Oct-1992 | K6: =DATEDIF(J6,DATE(2023,6,8),"Y") -> 30
A7: ? | B7: 1991 | C7: Nov | D7: 22 | E7: 2 | F7: 38711 | G7: tier - 1 | H7: tier - 3 | I7: R1011 | J7: =D7&"-"&C7&"-"&B7 -> 22-Nov-1991 | K7: =DATEDIF(J7,DATE(2023,6,8),"Y") -> 31
A8: Id1 | B8: 1968 | C8: Oct | D8: 12 | E8: 0 | F8: 63770.43 | G8: tier - 1 | H8: tier - 3 | I8: R1013 | J8: =D8&"-"&C8&"-"&B8 -> 12-Oct-1968 | K8: =DATEDIF(J8,DATE(2023,6,8),"Y") -> 54
A9: Id10 | B9: 1978 | C9: Dec | D9: 29 | E9: 0 | F9: 48885.14 | G9: tier - 1 | H9: tier - 2 | I9: R1013 | J9: =D9&"-"&C9&"-"&B9 -> 29-Dec-1978 | K9: =DATEDIF(J9,DATE(2023,6,8),"Y") -> 44
A10: Id100 | B10: 1977 | C10: Jun | D10: 27 | E10: 2 | F10: 40284.38 | G10: tier - 1 | H10: tier - 3 | I10: R1012 | J10: =D10&"-"&C10&"-"&B10 -> 27-Jun-1977 | K10: =DATEDIF(J10,DATE(2023,6,8),"Y") -> 45
A11: Id1000 | B11: 1989 | C11: Dec | D11: 17 | E11: 3 | F11: 11250.43 | G11: tier - 3 | H11: tier - 2 | I11: R1026 | J11: =D11&"-"&C11&"-"&B11 -> 17-Dec-1989 | K11: =DATEDIF(J11,DATE(2023,6,8),"Y") -> 33
A12: Id1001 | B12: 1969 | C12: Dec | D12: 30 | E12: 2 | F12: 11244.38 | G12: tier - 3 | H12: tier - 1 | I12: R1016 | J12: =D12&"-"&C12&"-"&B12 -> 30-Dec-1969 | K12: =DATEDIF(J12,DATE(2023,6,8),"Y") -> 53
A13: Id1002 | B13: 1976 | C13: Jun | D13: 28 | E13: 2 | F13: 11217.35 | G13: tier - 3 | H13: tier - 2 | I13: R1025 | J13: =D13&"-"&C13&"-"&B13 -> 28-Jun-1976 | K13: =DATEDIF(J13,DATE(2023,6,8),"Y") -> 46
... A29: Id1017 | B29: 2001 | C29: Dec | D29: 17 | E29: 0 | F29: 11046.02 | G29: tier - 3 | H29: tier - 1 | I29: R1026 | J29: =D29&"-"&C29&"-"&B29 -> 17-Dec-2001 | K29: =DATEDIF(J29,DATE(2023,6,8),"Y") -> 21
A30: Id1018 | B30: 1974 | C30: Aug | D30: 30 | E30: 0 | F30: 11037.85 | G30: tier - 3 | H30: tier - 2 | I30: R1025 | J30: =D30&"-"&C30&"-"&B30 -> 30-Aug-1974 | K30: =DATEDIF(J30,DATE(2023,6,8),"Y") -> 48 | M30: "?" Values in table | O30: =COUNTIF(A1:I2344,"?") -> 6 | Q30: Avg of Year | R30: =AVERAGE(B2:B2344) -> 1982.8417
A31: Id1019 | B31: 1989 | C31: Oct | D31: 25 | E31: 3 | F31: 11037.51 | G31: tier - 3 | H31: tier - 1 | I31: R1012 | J31: =D31&"-"&C31&"-"&B31 -> 25-Oct-1989 | K31: =DATEDIF(J31,DATE(2023,6,8),"Y") -> 33 | Q31: Average rounded to the nearest integer. | R31: =ROUND(AVERAGE(B2:B2344),0) -> 1983
A32: Id102 | B32: 1981 | C32: Jul | D32: 28 | E32: 1 | F32: 40208.56 | G32: tier - 1 | H32: tier - 2 | I32: R1011 | J32: =D32&"-"&C32&"-"&B32 -> 28-Jul-1981 | K32: =DATEDIF(J32,DATE(2023,6,8),"Y") -> 41 | M32: Customer ID | O32: =COUNTIF(A2:A2344,"?") -> 6
A33: Id1020 | B33: 1974 | C33: Dec | D33: 10 | E33: 4 | F33: 11033.66 | G33: tier - 3 | H33: tier - 3 | I33: R1012 | J33: =D33&"-"&C33&"-"&B33 -> 10-Dec-1974 | K33: =DATEDIF(J33,DATE(2023,6,8),"Y") -> 48 | M33: year | O33: =COUNTIF(B2:B2344,"?") -> 0 | Q33: Mode of Hospital tier
A34: Id1021 | B34: 1996 | C34: Jul | D34: 21 | E34: 0 | F34: 11028.56 | G34: tier - 3 | H34: tier - 3 | I34: R1012 | J34: =D34&"-"&C34&"-"&B34 -> 21-Jul-1996 | K34: =DATEDIF(J34,DATE(2023,6,8),"Y") -> 26 | M34: Month | O34: =COUNTIF(C2:C2344,"?") -> 0
A35: Id1022 | B35: 1991 | C35: Jun | D35: 26 | E35: 3 | F35: 11018.05 | G35: tier - 3 | H35: tier - 2 | I35: R1012 | J35: =D35&"-"&C35&"-"&B35 -> 26-Jun-1991 | K35: =DATEDIF(J35,DATE(2023,6,8),"Y") -> 31 | M35: date | O35: =COUNTIF(D2:D2344,"?") -> 0 | Q35: tier - 1 | R35: =COUNTIF(G2:G2344,G4) -> 309
A36: Id1023 | B36: 1974 | C36: Dec | D36: 15 | E36: 4 | F36: 11015.17 | G36: tier - 3 | H36: tier - 1 | I36: R1012 | J36: =D36&"-"&C36&"-"&B36 -> 15-Dec-1974 | K36: =DATEDIF(J36,DATE(2023,6,8),"Y") -> 48 | M36: children | O36: =COUNTIF(E2:E2344,"?") -> 0 | Q36: tier - 2 | R36: =COUNTIF(G2:G2344,G2052) -> 1340
A37: Id1024 | B37: 1968 | C37: Oct | D37: 24 | E37: 2 | F37: 11013.71 | G37: tier - 3 | H37: tier - 1 | I37: R1013 | J37: =D37&"-"&C37&"-"&B37 -> 24-Oct-1968 | K37: =DATEDIF(J37,DATE(2023,6,8),"Y") -> 54 | M37: charges | O37: =COUNTIF(F2:F2344,"?") -> 0 | Q37: tier - 3 | R37: =COUNTIF(G2:G2344,G2327) -> 694
A38: Id1025 | B38: 2000 | C38: Sep | D38: 17 | E38: 0 | F38: 10991.58 | G38: tier - 3 | H38: tier - 3 | I38: R1012 | J38: =D38&"-"&C38&"-"&B38 -> 17-Sep-2000 | K38: =DATEDIF(J38,DATE(2023,6,8),"Y") -> 22 | M38: Hospital tier | O38: =COUNTIF(G2:G2344,"?") -> 0 | Q38: There for the most repeated value of Hospital tier is tier - 2.
A39: Id1026 | B39: 1965 | C39: Dec | D39: 18 | E39: 0 | F39: 10982.5 | G39: tier - 3 | H39: tier - 3 | I39: R1013 | J39: =D39&"-"&C39&"-"&B39 -> 18-Dec-1965 | K39: =DATEDIF(J39,DATE(2023,6,8),"Y") -> 57 | M39: City tier | O39: =COUNTIF(H2:H2344,"?") -> 0
A40: Id1027 | B40: 1973 | C40: Oct | D40: 21 | E40: 4 | F40: 10977.21 | G40: tier - 3 | H40: tier - 1 | I40: R1013 | J40: =D40&"-"&C40&"-"&B40 -> 21-Oct-1973 | K40: =DATEDIF(J40,DATE(2023,6,8),"Y") -> 49 | M40: State ID | O40: =COUNTIF(I2:I2344,"?") -> 0
A41: Id1028 | B41: 1966 | C41: Jul | D41: 9 | E41: 0 | F41: 10976.25 | G41: tier - 3 | H41: tier - 2 | I41: R1012 | J41: =D41&"-"&C41&"-"&B41 -> 9-Jul-1966 | K41: =DATEDIF(J41,DATE(2023,6,8),"Y") -> 56 | Q41: Mode of City tier
A42: Id1029 | B42: 1965 | C42: Jun | D42: 19 | E42: 0 | F42: 10965.45 | G42: tier - 3 | H42: tier - 2 | I42: R1011 | J42: =D42&"-"&C42&"-"&B42 -> 19-Jun-1965 | K42: =DATEDIF(J42,DATE(2023,6,8),"Y") -> 57
A43: Id103 | B43: 1979 | C43: Aug | D43: 18 | E43: 2 | F43: 40204.83 | G43: tier - 1 | H43: tier - 3 | I43: R1012 | J43: =D43&"-"&C43&"-"&B43 -> 18-Aug-1979 | K43: =DATEDIF(J43,DATE(2023,6,8),"Y") -> 43 | Q43: tier - 1 | R43: =COUNTIF(H2:H2344,H28) -> 734
A44: Id1030 | B44: 1969 | C44: Aug | D44: 14 | E44: 1 | F44: 10959.69 | G44: tier - 3 | H44: tier - 3 | I44: R1012 | J44: =D44&"-"&C44&"-"&B44 -> 14-Aug-1969 | K44: =DATEDIF(J44,DATE(2023,6,8),"Y") -> 53 | Q44: tier - 2 | R44: =COUNTIF(H2:H2344,H32) -> 813
A45: Id1031 | B45: 1965 | C45: Dec | D45: 4 | E45: 0 | F45: 10959.33 | G45: tier - 3 | H45: tier - 3 | I45: R1011 | J45: =D45&"-"&C45&"-"&B45 -> 4-Dec-1965 | K45: =DATEDIF(J45,DATE(2023,6,8),"Y") -> 57 | Q45: tier - 3 | R45: =COUNTIF(H2:H2344,H33) -> 796
A46: Id1032 | B46: 1969 | C46: Nov | D46: 10 | E46: 1 | F46: 10942.13 | G46: tier - 3 | H46: tier - 3 | I46: R1012 | J46: =D46&"-"&C46&"-"&B46 -> 10-Nov-1969 | K46: =DATEDIF(J46,DATE(2023,6,8),"Y") -> 53 | Q46: There for the most repeated value of City tier is tier - 2.
A47: Id1033 | B47: 1968 | C47: Nov | D47: 12 | E47: 1 | F47: 10928.85 | G47: tier - 3 | H47: tier - 3 | I47: R1013 | J47: =D47&"-"&C47&"-"&B47 -> 12-Nov-1968 | K47: =DATEDIF(J47,DATE(2023,6,8),"Y") -> 54
A48: Id1034 | B48: 1968 | C48: Nov | D48: 13 | E48: 0 | F48: 10923.93 | G48: tier - 3 | H48: tier - 1 | I48: R1024 | J48: =D48&"-"&C48&"-"&B48 -> 13-Nov-1968 | K48: =DATEDIF(J48,DATE(2023,6,8),"Y") -> 54
A49: Id1035 | B49: 1994 | C49: Sep | D49: 6 | E49: 0 | F49: 10886.66 | G49: tier - 3 | H49: tier - 3 | I49: R1012 | J49: =D49&"-"&C49&"-"&B49 -> 6-Sep-1994 | K49: =DATEDIF(J49,DATE(2023,6,8),"Y") -> 28
A50: Id1036 | B50: 1971 | C50: Dec | D50: 20 | E50: 2 | F50: 10848.13 | G50: tier - 3 | H50: tier - 3 | I50: R1012 | J50: =D50&"-"&C50&"-"&B50 -> 20-Dec-1971 | K50: =DATEDIF(J50,DATE(2023,6,8),"Y") -> 51
A51: Id1037 | B51: 1968 | C51: Jul | D51: 28 | E51: 1 | F51: 10825.25 | G51: tier - 3 | H51: tier - 3 | I51: R1012 | J51: =D51&"-"&C51&"-"&B51 -> 28-Jul-1968 | K51: =DATEDIF(J51,DATE(2023,6,8),"Y") -> 54
A52: Id1038 | B52: 1967 | C52: Oct | D52: 2 | E52: 1 | F52: 10807.49 | G52: tier - 3 | H52: tier - 2 | I52: R1013 | J52: =D52&"-"&C52&"-"&B52 -> 2-Oct-1967 | K52: =DATEDIF(J52,DATE(2023,6,8),"Y") -> 55
A53: Id1039 | B53: 1970 | C53: Dec | D53: 18 | E53: 2 | F53: 10806.84 | G53: tier - 3 | H53: tier - 2 | I53: R1011 | J53: =D53&"-"&C53&"-"&B53 -> 18-Dec-1970 | K53: =DATEDIF(J53,DATE(2023,6,8),"Y") -> 52
A54: Id104 | B54: 1985 | C54: Oct | D54: 21 | E54: 4 | F54: 40182.25 | G54: tier - 1 | H54: tier - 2 | I54: R1011 | J54: =D54&"-"&C54&"-"&B54 -> 21-Oct-1985 | K54: =DATEDIF(J54,DATE(2023,6,8),"Y") -> 37
A55: Id1040 | B55: 1970 | C55: Oct | D55: 28 | E55: 1 | F55: 10797.34 | G55: tier - 3 | H55: tier - 2 | I55: R1023 | J55: =D55&"-"&C55&"-"&B55 -> 28-Oct-1970 | K55: =DATEDIF(J55,DATE(2023,6,8),"Y") -> 52
...

Sheet Sheet1

Sheet Healthcare
A1: Customer ID | B1: First Name | C1: BMI | D1: HBA1C | E1: Heart Issues | F1: Any Transplants | G1: Cancer history | H1: NumberOfMajorSurgeries | I1: smoker | J1: Weight Status | K1: Diabetes Status | L1: Date of Birth | M1: charges | N1: Hospital tier | O1: City tier | P1: State ID | Q1: Age
A2: Id1 | B2: =VLOOKUP(Healthcare!A2,'Customer Names'!A2:E2336,4,FALSE) -> Kelly | C2: =_xlfn.XLOOKUP(A2,'Medical Examinations'!$A$2:$A$2336,'Medical Examinations'!$B$2:$B$2336,"NA",0,1) -> 47.41 | D2: =_xlfn.XLOOKUP(A2,'Medical Examinations'!$A$2:$A$2336,'Medical Examinations'!$C$2:$C$2336) -> 7.47 | E2: =_xlfn.XLOOKUP(A2,'Medical Examinations'!$A$2:$A$2336,'Medical Examinations'!$D$2:$D$2336) -> No | F2: =_xlfn.XLOOKUP(A2,'Medical Examinations'!$A$2:$A$2336,'Medical Examinations'!$E$2:$E$2336) -> No | G2: =_xlfn.XLOOKUP(A2,'Medical Examinations'!$A$2:$A$2336,'Medical Examinations'!$F$2:$F$2336) -> No | H2: =_xlfn.XLOOKUP(A2,'Medical Examinations'!$A$2:$A$2336,'Medical Examinations'!$G$2:$G$2336) -> 0 | I2: =_xlfn.XLOOKUP(A2,'Medical Examinations'!$A$2:$A$2336,'Medical Examinations'!$H$2:$H$2336) -> Yes | J2: =VLOOKUP(A2,'Medical Examinations'!$A$2:$J$2336,9,FALSE) -> Obesity | K2: =VLOOKUP(A2,'Medical Examinations'!$A$2:$J$2336,10,FALSE) -> Diabetes | L2: =_xlfn.XLOOKUP(A2,'Hospitalisation Details'!$A$2:$A$2345,'Hospitalisation Details'!$J$2:$J$2345,"") -> 12-Oct-1968 | M2: =_xlfn.XLOOKUP(A2,'Hospitalisation Details'!$A$2:$A$2344,'Hospitalisation Details'!$F$2:$F$2344," ",0,1) -> 63770.43 | N2: =_xlfn.XLOOKUP(A2,'Hospitalisation Details'!$A$2:$A$2344,'Hospitalisation Details'!$G$2:$G$2344," ",0,1) -> tier - 1 | O2: =_xlfn.XLOOKUP(A2,'Hospitalisation Details'!$A$2:$A$2344,'Hospitalisation Details'!$H$2:$H$2344," ",0,1) -> tier - 3 | P2: =_xlfn.XLOOKUP(A2,'Hospitalisation Details'!$A$2:$A$2344,'Hospitalisation Details'!$I$2:$I$2344," ",0,1) -> R1013 | Q2: =_xlfn.XLOOKUP(A2,'Hospitalisation Details'!$A$2:$A$2344,'Hospitalisation Details'!$K$2:$K$2344," ",0,1) -> 54
A3: Id2 | B3: =VLOOKUP(Healthcare!A3,'Customer Names'!A3:E2337,4,FALSE) -> Matthew D | C3: =_xlfn.XLOOKUP(A3,'Medical Examinations'!$A$2:$A$2336,'Medical Examinations'!$B$2:$B$2336,"NA",0,1) -> 30.36 | D3: =_xlfn.XLOOKUP(A3,'Medical Examinations'!$A$2:$A$2336,'Medical Examinations'!$C$2:$C$2336) -> 5.77 | E3: =_xlfn.XLOOKUP(A3,'Medical Examinations'!$A$2:$A$2336,'Medical Examinations'!$D$2:$D$2336) -> No | F3: =_xlfn.XLOOKUP(A3,'Medical Examinations'!$A$2:$A$2336,'Medical Examinations'!$E$2:$E$2336) -> No | G3: =_xlfn.XLOOKUP(A3,'Medical Examinations'!$A$2:$A$2336,'Medical Examinations'!$F$2:$F$2336) -> No | H3: =_xlfn.XLOOKUP(A3,'Medical Examinations'!$A$2:$A$2336,'Medical Examinations'!$G$2:$G$2336) -> 0 | I3: =_xlfn.XLOOKUP(A3,'Medical Examinations'!$A$2:$A$2336,'Medical Examinations'!$H$2:$H$2336) -> Yes | J3: =VLOOKUP(A3,'Medical Examinations'!$A$2:$J$2336,9,FALSE) -> Obesity | K3: =VLOOKUP(A3,'Medical Examinations'!$A$2:$J$2336,10,FALSE) -> Prediabetes | L3: =_xlfn.XLOOKUP(A3,'Hospitalisation Details'!$A$2:$A$2345,'Hospitalisation Details'!$J$2:$J$2345,"") -> 8-Jun-1977 | M3: =_xlfn.XLOOKUP(A3,'Hospitalisation Details'!$A$2:$A$2344,'Hospitalisation Details'!$F$2:$F$2344," ",0,1) -> 62592.87 | N3: =_xlfn.XLOOKUP(A3,'Hospitalisation Details'!$A$2:$A$2344,'Hospitalisation Details'!$G$2:$G$2344," ",0,1) -> tier - 2 | O3: =_xlfn.XLOOKUP(A3,'Hospitalisation Details'!$A$2:$A$2344,'Hospitalisation Details'!$H$2:$H$2344," ",0,1) -> tier - 3 | P3: =_xlfn.XLOOKUP(A3,'Hospitalisation Details'!$A$2:$A$2344,'Hospitalisation Details'!$I$2:$I$2344," ",0,1) -> R1013 | Q3: =_xlfn.XLOOKUP(A3,'Hospitalisation Details'!$A$2:$A$2344,'Hospitalisation Details'!$K$2:$K$2344," ",0,1) -> 46
A4: Id3 | B4: =VLOOKUP(Healthcare!A4,'Customer Names'!A4:E2338,4,FALSE) -> Phil | C4: =_xlfn.XLOOKUP(A4,'Medical Examinations'!$A$2:$A$2336,'Medical Examinations'!$B$2:$B$2336,"NA",0,1) -> 34.485 | D4: =_xlfn.XLOOKUP(A4,'Medical Examinations'!$A$2:$A$2336,'Medical Examinations'!$C$2:$C$2336) -> 11.87 | E4: =_xlfn.XLOOKUP(A4,'Medical Examinations'!$A$2:$A$2336,'Medical Examinations'!$D$2:$D$2336) -> Yes | F4: =_xlfn.XLOOKUP(A4,'Medical Examinations'!$A$2:$A$2336,'Medical Examinations'!$E$2:$E$2336) -> No | G4: =_xlfn.XLOOKUP(A4,'Medical Examinations'!$A$2:$A$2336,'Medical Examinations'!$F$2:$F$2336) -> No | H4: =_xlfn.XLOOKUP(A4,'Medical Examinations'!$A$2:$A$2336,'Medical Examinations'!$G$2:$G$2336) -> 2 | I4: =_xlfn.XLOOKUP(A4,'Medical Examinations'!$A$2:$A$2336,'Medical Examinations'!$H$2:$H$2336) -> Yes | J4: =VLOOKUP(A4,'Medical Examinations'!$A$2:$J$2336,9,FALSE) -> Obesity | K4: =VLOOKUP(A4,'Medical Examinations'!$A$2:$J$2336,10,FALSE) -> Diabetes | L4: =_xlfn.XLOOKUP(A4,'Hospitalisation Details'!$A$2:$A$2345,'Hospitalisation Details'!$J$2:$J$2345,"") -> 11-Sep-1970 | M4: =_xlfn.XLOOKUP(A4,'Hospitalisation Details'!$A$2:$A$2344,'Hospitalisation Details'!$F$2:$F$2344," ",0,1) -> 60021.4 | N4: =_xlfn.XLOOKUP(A4,'Hospitalisation Details'!$A$2:$A$2344,'Hospitalisation Details'!$G$2:$G$2344," ",0,1) -> tier - 1 | O4: =_xlfn.XLOOKUP(A4,'Hospitalisation Details'!$A$2:$A$2344,'Hospitalisation Details'!$H$2:$H$2344," ",0,1) -> tier - 1 | P4: =_xlfn.XLOOKUP(A4,'Hospitalisation Details'!$A$2:$A$2344,'Hospitalisation Details'!$I$2:$I$2344," ",0,1) -> R1012 | Q4: =_xlfn.XLOOKUP(A4,'Hospitalisation Details'!$A$2:$A$2344,'Hospitalisation Details'!$K$2:$K$2344," ",0,1) -> 52
A5: Id4 | B5: =VLOOKUP(Healthcare!A5,'Customer Names'!A5:E2339,4,FALSE) -> Kelsey | C5: =_xlfn.XLOOKUP(A5,'Medical Examinations'!$A$2:$A$2336,'Medical Examinations'!$B$2:$B$2336,"NA",0,1) -> 38.095 | D5: =_xlfn.XLOOKUP(A5,'Medical Examinations'!$A$2:$A$2336,'Medical Examinations'!$C$2:$C$2336) -> 6.05 | E5: =_xlfn.XLOOKUP(A5,'Medical Examinations'!$A$2:$A$2336,'Medical Examinations'!$D$2:$D$2336) -> No | F5: =_xlfn.XLOOKUP(A5,'Medical Examinations'!$A$2:$A$2336,'Medical Examinations'!$E$2:$E$2336) -> No | G5: =_xlfn.XLOOKUP(A5,'Medical Examinations'!$A$2:$A$2336,'Medical Examinations'!$F$2:$F$2336) -> No | H5: =_xlfn.XLOOKUP(A5,'Medical Examinations'!$A$2:$A$2336,'Medical Examinations'!$G$2:$G$2336) -> 0 | I5: =_xlfn.XLOOKUP(A5,'Medical Examinations'!$A$2:$A$2336,'Medical Examinations'!$H$2:$H$2336) -> Yes | J5: =VLOOKUP(A5,'Medical Examinations'!$A$2:$J$2336,9,FALSE) -> Obesity | K5: =VLOOKUP(A5,'Medical Examinations'!$A$2:$J$2336,10,FALSE) -> Prediabetes | L5: =_xlfn.XLOOKUP(A5,'Hospitalisation Details'!$A$2:$A$2345,'Hospitalisation Details'!$J$2:$J$2345,"") -> 6-Jun-1991 | M5: =_xlfn.XLOOKUP(A5,'Hospitalisation Details'!$A$2:$A$2344,'Hospitalisation Details'!$F$2:$F$2344," ",0,1) -> 58571.07 | N5: =_xlfn.XLOOKUP(A5,'Hospitalisation Details'!$A$2:$A$2344,'Hospitalisation Details'!$G$2:$G$2344," ",0,1) -> tier - 1 | O5: =_xlfn.XLOOKUP(A5,'Hospitalisation Details'!$A$2:$A$2344,'Hospitalisation Details'!$H$2:$H$2344," ",0,1) -> tier - 3 | P5: =_xlfn.XLOOKUP(A5,'Hospitalisation Details'!$A$2:$A$2344,'Hospitalisation Details'!$I$2:$I$2344," ",0,1) -> R1024 | Q5: =_xlfn.XLOOKUP(A5,'Hospitalisation Details'!$A$2:$A$2344,'Hospitalisation Details'!$K$2:$K$2344," ",0,1) -> 32
A6: Id5 | B6: =VLOOKUP(Healthcare!A6,'Customer Names'!A6:E2340,4,FALSE) -> Kristyn | C6: =_xlfn.XLOOKUP(A6,'Medical Examinations'!$A$2:$A$2336,'Medical Examinations'!$B$2:$B$2336,"NA",0,1) -> 35.53 | D6: =_xlfn.XLOOKUP(A6,'Medical Examinations'!$A$2:$A$2336,'Medical Examinations'!$C$2:$C$2336) -> 5.45 | E6: =_xlfn.XLOOKUP(A6,'Medical Examinations'!$A$2:$A$2336,'Medical Examinations'!$D$2:$D$2336) -> No | F6: =_xlfn.XLOOKUP(A6,'Medical Examinations'!$A$2:$A$2336,'Medical Examinations'!$E$2:$E$2336) -> No | G6: =_xlfn.XLOOKUP(A6,'Medical Examinations'!$A$2:$A$2336,'Medical Examinations'!$F$2:$F$2336) -> No | H6: =_xlfn.XLOOKUP(A6,'Medical Examinations'!$A$2:$A$2336,'Medical Examinations'!$G$2:$G$2336) -> 0 | I6: =_xlfn.XLOOKUP(A6,'Medical Examinations'!$A$2:$A$2336,'Medical Examinations'!$H$2:$H$2336) -> Yes | J6: =VLOOKUP(A6,'Medical Examinations'!$A$2:$J$2336,9,FALSE) -> Obesity | K6: =VLOOKUP(A6,'Medical Examinations'!$A$2:$J$2336,10,FALSE) -> Normal | L6: =_xlfn.XLOOKUP(A6,'Hospitalisation Details'!$A$2:$A$2345,'Hospitalisation Details'!$J$2:$J$2345,"") -> 19-Jun-1989 | M6: =_xlfn.XLOOKUP(A6,'Hospitalisation Details'!$A$2:$A$2344,'Hospitalisation Details'!$F$2:$F$2344," ",0,1) -> 55135.4 | N6: =_xlfn.XLOOKUP(A6,'Hospitalisation Details'!$A$2:$A$2344,'Hospitalisation Details'!$G$2:$G$2344," ",0,1) -> tier - 1 | O6: =_xlfn.XLOOKUP(A6,'Hospitalisation Details'!$A$2:$A$2344,'Hospitalisation Details'!$H$2:$H$2344," ",0,1) -> tier - 2 | P6: =_xlfn.XLOOKUP(A6,'Hospitalisation Details'!$A$2:$A$2344,'Hospitalisation Details'!$I$2:$I$2344," ",0,1) -> R1012 | Q6: =_xlfn.XLOOKUP(A6,'Hospitalisation Details'!$A$2:$A$2344,'Hospitalisation Details'!$K$2:$K$2344," ",0,1) -> 33
A7: Id6 | B7: =VLOOKUP(Healthcare!A7,'Customer Names'!A7:E2341,4,FALSE) -> Russell B. | C7: =_xlfn.XLOOKUP(A7,'Medical Examinations'!$A$2:$A$2336,'Medical Examinations'!$B$2:$B$2336,"NA",0,1) -> 32.8 | D7: =_xlfn.XLOOKUP(A7,'Medical Examinations'!$A$2:$A$2336,'Medical Examinations'!$C$2:$C$2336) -> 6.59 | E7: =_xlfn.XLOOKUP(A7,'Medical Examinations'!$A$2:$A$2336,'Medical Examinations'!$D$2:$D$2336) -> No | F7: =_xlfn.XLOOKUP(A7,'Medical Examinations'!$A$2:$A$2336,'Medical Examinations'!$E$2:$E$2336) -> No | G7: =_xlfn.XLOOKUP(A7,'Medical Examinations'!$A$2:$A$2336,'Medical Examinations'!$F$2:$F$2336) -> No | H7: =_xlfn.XLOOKUP(A7,'Medical Examinations'!$A$2:$A$2336,'Medical Examinations'!$G$2:$G$2336) -> 0 | I7: =_xlfn.XLOOKUP(A7,'Medical Examinations'!$A$2:$A$2336,'Medical Examinations'!$H$2:$H$2336) -> Yes | J7: =VLOOKUP(A7,'Medical Examinations'!$A$2:$J$2336,9,FALSE) -> Obesity | K7: =VLOOKUP(A7,'Medical Examinations'!$A$2:$J$2336,10,FALSE) -> Diabetes | L7: =_xlfn.XLOOKUP(A7,'Hospitalisation Details'!$A$2:$A$2345,'Hospitalisation Details'!$J$2:$J$2345,"") -> 4-Aug-1962 | M7: =_xlfn.XLOOKUP(A7,'Hospitalisation Details'!$A$2:$A$2344,'Hospitalisation Details'!$F$2:$F$2344," ",0,1) -> 52590.83 | N7: =_xlfn.XLOOKUP(A7,'Hospitalisation Details'!$A$2:$A$2344,'Hospitalisation Details'!$G$2:$G$2344," ",0,1) -> tier - 1 | O7: =_xlfn.XLOOKUP(A7,'Hospitalisation Details'!$A$2:$A$2344,'Hospitalisation Details'!$H$2:$H$2344," ",0,1) -> tier - 3 | P7: =_xlfn.XLOOKUP(A7,'Hospitalisation Details'!$A$2:$A$2344,'Hospitalisation Details'!$I$2:$I$2344," ",0,1) -> R1011 | Q7: =_xlfn.XLOOKUP(A7,'Hospitalisation Details'!$A$2:$A$2344,'Hospitalisation Details'!$K$2:$K$2344," ",0,1) -> 60
A8: Id7 | B8: =VLOOKUP(Healthcare!A8,'Customer Names'!A8:E2342,4,FALSE) -> Scott | C8: =_xlfn.XLOOKUP(A8,'Medical Examinations'!$A$2:$A$2336,'Medical Examinations'!$B$2:$B$2336,"NA",0,1) -> 36.4 | D8: =_xlfn.XLOOKUP(A8,'Medical Examinations'!$A$2:$A$2336,'Medical Examinations'!$C$2:$C$2336) -> 6.07 | E8: =_xlfn.XLOOKUP(A8,'Medical Examinations'!$A$2:$A$2336,'Medical Examinations'!$D$2:$D$2336) -> No | F8: =_xlfn.XLOOKUP(A8,'Medical Examinations'!$A$2:$A$2336,'Medical Examinations'!$E$2:$E$2336) -> No | G8: =_xlfn.XLOOKUP(A8,'Medical Examinations'!$A$2:$A$2336,'Medical Examinations'!$F$2:$F$2336) -> No | H8: =_xlfn.XLOOKUP(A8,'Medical Examinations'!$A$2:$A$2336,'Medical Examinations'!$G$2:$G$2336) -> 0 | I8: =_xlfn.XLOOKUP(A8,'Medical Examinations'!$A$2:$A$2336,'Medical Examinations'!$H$2:$H$2336) -> Yes | J8: =VLOOKUP(A8,'Medical Examinations'!$A$2:$J$2336,9,FALSE) -> Obesity | K8: =VLOOKUP(A8,'Medical Examinations'!$A$2:$J$2336,10,FALSE) -> Prediabetes | L8: =_xlfn.XLOOKUP(A8,'Hospitalisation Details'!$A$2:$A$2345,'Hospitalisation Details'!$J$2:$J$2345,"") -> 27-Oct-1994 | M8: =_xlfn.XLOOKUP(A8,'Hospitalisation Details'!$A$2:$A$2344,'Hospitalisation Details'!$F$2:$F$2344," ",0,1) -> 51194.56 | N8: =_xlfn.XLOOKUP(A8,'Hospitalisation Details'!$A$2:$A$2344,'Hospitalisation Details'!$G$2:$G$2344," ",0,1) -> tier - 1 | O8: =_xlfn.XLOOKUP(A8,'Hospitalisation Details'!$A$2:$A$2344,'Hospitalisation Details'!$H$2:$H$2344," ",0,1) -> tier - 3 | P8: =_xlfn.XLOOKUP(A8,'Hospitalisation Details'!$A$2:$A$2344,'Hospitalisation Details'!$I$2:$I$2344," ",0,1) -> R1011 | Q8: =_xlfn.XLOOKUP(A8,'Hospitalisation Details'!$A$2:$A$2344,'Hospitalisation Details'!$K$2:$K$2344," ",0,1) -> 28
A9: Id8 | B9: =VLOOKUP(Healthcare!A9,'Customer Names'!A9:E2343,4,FALSE) -> Stephen | C9: =_xlfn.XLOOKUP(A9,'Medical Examinations'!$A$2:$A$2336,'Medical Examinations'!$B$2:$B$2336,"NA",0,1) -> 36.96 | D9: =_xlfn.XLOOKUP(A9,'Medical Examinations'!$A$2:$A$2336,'Medical Examinations'!$C$2:$C$2336) -> 7.93 | E9: =_xlfn.XLOOKUP(A9,'Medical Examinations'!$A$2:$A$2336,'Medical Examinations'!$D$2:$D$2336) -> No | F9: =_xlfn.XLOOKUP(A9,'Medical Examinations'!$A$2:$A$2336,'Medical Examinations'!$E$2:$E$2336) -> No | G9: =_xlfn.XLOOKUP(A9,'Medical Examinations'!$A$2:$A$2336,'Medical Examinations'!$F$2:$F$2336) -> No | H9: =_xlfn.XLOOKUP(A9,'Medical Examinations'!$A$2:$A$2336,'Medical Examinations'!$G$2:$G$2336) -> 3 | I9: =_xlfn.XLOOKUP(A9,'Medical Examinations'!$A$2:$A$2336,'Medical Examinations'!$H$2:$H$2336) -> Yes | J9: =VLOOKUP(A9,'Medical Examinations'!$A$2:$J$2336,9,FALSE) -> Obesity | K9: =VLOOKUP(A9,'Medical Examinations'!$A$2:$J$2336,10,FALSE) -> Diabetes | L9: =_xlfn.XLOOKUP(A9,'Hospitalisation Details'!$A$2:$A$2345,'Hospitalisation Details'!$J$2:$J$2345,"") -> 27-Jun-1958 | M9: =_xlfn.XLOOKUP(A9,'Hospitalisation Details'!$A$2:$A$2344,'Hospitalisation Details'!$F$2:$F$2344," ",0,1) -> 49577.66 | N9: =_xlfn.XLOOKUP(A9,'Hospitalisation Details'!$A$2:$A$2344,'Hospitalisation Details'!$G$2:$G$2344," ",0,1) -> tier - 2 | O9: =_xlfn.XLOOKUP(A9,'Hospitalisation Details'!$A$2:$A$2344,'Hospitalisation Details'!$H$2:$H$2344," ",0,1) -> tier - 2 | P9: =_xlfn.XLOOKUP(A9,'Hospitalisation Details'!$A$2:$A$2344,'Hospitalisation Details'!$I$2:$I$2344," ",0,1) -> R1013 | Q9: =_xlfn.XLOOKUP(A9,'Hospitalisation Details'!$A$2:$A$2344,'Hospitalisation Details'!$K$2:$K$2344," ",0,1) -> 64
A10: Id9 | B10: =VLOOKUP(Healthcare!A10,'Customer Names'!A10:E2344,4,FALSE) -> Patrick R. | C10: =_xlfn.XLOOKUP(A10,'Medical Examinations'!$A$2:$A$2336,'Medical Examinations'!$B$2:$B$2336,"NA",0,1) -> 41.14 | D10: =_xlfn.XLOOKUP(A10,'Medical Examinations'!$A$2:$A$2336,'Medical Examinations'!$C$2:$C$2336) -> 9.58 | E10: =_xlfn.XLOOKUP(A10,'Medical Examinations'!$A$2:$A$2336,'Medical Examinations'!$D$2:$D$2336) -> Yes | F10: =_xlfn.XLOOKUP(A10,'Medical Examinations'!$A$2:$A$2336,'Medical Examinations'!$E$2:$E$2336) -> No | G10: =_xlfn.XLOOKUP(A10,'Medical Examinations'!$A$2:$A$2336,'Medical Examinations'!$F$2:$F$2336) -> Yes | H10: =_xlfn.XLOOKUP(A10,'Medical Examinations'!$A$2:$A$2336,'Medical Examinations'!$G$2:$G$2336) -> 1 | I10: =_xlfn.XLOOKUP(A10,'Medical Examinations'!$A$2:$A$2336,'Medical Examinations'!$H$2:$H$2336) -> Yes | J10: =VLOOKUP(A10,'Medical Examinations'!$A$2:$J$2336,9,FALSE) -> Obesity | K10: =VLOOKUP(A10,'Medical Examinations'!$A$2:$J$2336,10,FALSE) -> Diabetes | L10: =_xlfn.XLOOKUP(A10,'Hospitalisation Details'!$A$2:$A$2345,'Hospitalisation Details'!$J$2:$J$2345,"") -> 4-Sep-1963 | M10: =_xlfn.XLOOKUP(A10,'Hospitalisation Details'!$A$2:$A$2344,'Hospitalisation Details'!$F$2:$F$2344," ",0,1) -> 48970.25 | N10: =_xlfn.XLOOKUP(A10,'Hospitalisation Details'!$A$2:$A$2344,'Hospitalisation Details'!$G$2:$G$2344," ",0,1) -> tier - 1 | O10: =_xlfn.XLOOKUP(A10,'Hospitalisation Details'!$A$2:$A$2344,'Hospitalisation Details'!$H$2:$H$2344," ",0,1) -> tier - 2 | P10: =_xlfn.XLOOKUP(A10,'Hospitalisation Details'!$A$2:$A$2344,'Hospitalisation Details'!$I$2:$I$2344," ",0,1) -> R1013 | Q10: =_xlfn.XLOOKUP(A10,'Hospitalisation Details'!$A$2:$A$2344,'Hospitalisation Details'!$K$2:$K$2344," ",0,1) -> 59
A11: Id10 | B11: =VLOOKUP(Healthcare!A11,'Customer Names'!A11:E2345,4,FALSE) -> Brooke N. | C11: =_xlfn.XLOOKUP(A11,'Medical Examinations'!$A$2:$A$2336,'Medical Examinations'!$B$2:$B$2336,"NA",0,1) -> 38.06 | D11: =_xlfn.XLOOKUP(A11,'Medical Examinations'!$A$2:$A$2336,'Medical Examinations'!$C$2:$C$2336) -> 10.79 | E11: =_xlfn.XLOOKUP(A11,'Medical Examinations'!$A$2:$A$2336,'Medical Examinations'!$D$2:$D$2336) -> No | F11: =_xlfn.XLOOKUP(A11,'Medical Examinations'!$A$2:$A$2336,'Medical Examinations'!$E$2:$E$2336) -> No | G11: =_xlfn.XLOOKUP(A11,'Medical Examinations'!$A$2:$A$2336,'Medical Examinations'!$F$2:$F$2336) -> No | H11: =_xlfn.XLOOKUP(A11,'Medical Examinations'!$A$2:$A$2336,'Medical Examinations'!$G$2:$G$2336) -> 0 | I11: =_xlfn.XLOOKUP(A11,'Medical Examinations'!$A$2:$A$2336,'Medical Examinations'!$H$2:$H$2336) -> Yes | J11: =VLOOKUP(A11,'Medical Examinations'!$A$2:$J$2336,9,FALSE) -> Obesity | K11: =VLOOKUP(A11,'Medical Examinations'!$A$2:$J$2336,10,FALSE) -> Diabetes | L11: =_xlfn.XLOOKUP(A11,'Hospitalisation Details'!$A$2:$A$2345,'Hospitalisation Details'!$J$2:$J$2345,"") -> 29-Dec-1978 | M11: =_xlfn.XLOOKUP(A11,'Hospitalisation Details'!$A$2:$A$2344,'Hospitalisation Details'!$F$2:$F$2344," ",0,1) -> 48885.14 | N11: =_xlfn.XLOOKUP(A11,'Hospitalisation Details'!$A$2:$A$2344,'Hospitalisation Details'!$G$2:$G$2344," ",0,1) -> tier - 1 | O11: =_xlfn.XLOOKUP(A11,'Hospitalisation Details'!$A$2:$A$2344,'Hospitalisation Details'!$H$2:$H$2344," ",0,1) -> tier - 2 | P11: =_xlfn.XLOOKUP(A11,'Hospitalisation Details'!$A$2:$A$2344,'Hospitalisation Details'!$I$2:$I$2344," ",0,1) -> R1013 | Q11: =_xlfn.XLOOKUP(A11,'Hospitalisation Details'!$A$2:$A$2344,'Hospitalisation Details'!$K$2:$K$2344," ",0,1) -> 44
A12: Id11 | B12: =VLOOKUP(Healthcare!A12,'Customer Names'!A12:E2346,4,FALSE) -> Paola Andrea | C12: =_xlfn.XLOOKUP(A12,'Medical Examinations'!$A$2:$A$2336,'Medical Examinations'!$B$2:$B$2336,"NA",0,1) -> 37.7 | D12: =_xlfn.XLOOKUP(A12,'Medical Examinations'!$A$2:$A$2336,'Medical Examinations'!$C$2:$C$2336) -> 5.96 | E12: =_xlfn.XLOOKUP(A12,'Medical Examinations'!$A$2:$A$2336,'Medical Examinations'!$D$2:$D$2336) -> Yes | F12: =_xlfn.XLOOKUP(A12,'Medical Examinations'!$A$2:$A$2336,'Medical Examinations'!$E$2:$E$2336) -> No | G12: =_xlfn.XLOOKUP(A12,'Medical Examinations'!$A$2:$A$2336,'Medical Examinations'!$F$2:$F$2336) -> No | H12: =_xlfn.XLOOKUP(A12,'Medical Examinations'!$A$2:$A$2336,'Medical Examinations'!$G$2:$G$2336) -> 2 | I12: =_xlfn.XLOOKUP(A12,'Medical Examinations'!$A$2:$A$2336,'Medical Examinations'!$H$2:$H$2336) -> Yes | J12: =VLOOKUP(A12,'Medical Examinations'!$A$2:$J$2336,9,FALSE) -> Obesity | K12: =VLOOKUP(A12,'Medical Examinations'!$A$2:$J$2336,10,FALSE) -> Prediabetes | L12: =_xlfn.XLOOKUP(A12,'Hospitalisation Details'!$A$2:$A$2345,'Hospitalisation Details'!$J$2:$J$2345,"") -> 22-Jul-1959 | M12: =_xlfn.XLOOKUP(A12,'Hospitalisation Details'!$A$2:$A$2344,'Hospitalisation Details'!$F$2:$F$2344," ",0,1) -> 48824.45 | N12: =_xlfn.XLOOKUP(A12,'Hospitalisation Details'!$A$2:$A$2344,'Hospitalisation Details'!$G$2:$G$2344," ",0,1) -> tier - 2 | O12: =_xlfn.XLOOKUP(A12,'Hospitalisation Details'!$A$2:$A$2344,'Hospitalisation Details'!$H$2:$H$2344," ",0,1) -> tier - 1 | P12: =_xlfn.XLOOKUP(A12,'Hospitalisation Details'!$A$2:$A$2344,'Hospitalisation Details'!$I$2:$I$2344," ",0,1) -> R1011 | Q12: =_xlfn.XLOOKUP(A12,'Hospitalisation Details'!$A$2:$A$2344,'Hospitalisation Details'!$K$2:$K$2344," ",0,1) -> 63
A13: Id12 | B13: =VLOOKUP(Healthcare!A13,'Customer Names'!A13:E2347,4,FALSE) -> David | C13: =_xlfn.XLOOKUP(A13,'Medical Examinations'!$A$2:$A$2336,'Medical Examinations'!$B$2:$B$2336,"NA",0,1) -> 42.13 | D13: =_xlfn.XLOOKUP(A13,'Medical Examinations'!$A$2:$A$2336,'Medical Examinations'!$C$2:$C$2336) -> 11.9 | E13: =_xlfn.XLOOKUP(A13,'Medical Examinations'!$A$2:$A$2336,'Medical Examinations'!$D$2:$D$2336) -> No | F13: =_xlfn.XLOOKUP(A13,'Medical Examinations'!$A$2:$A$2336,'Medical Examinations'!$E$2:$E$2336) -> No | G13: =_xlfn.XLOOKUP(A13,'Medical Examinations'!$A$2:$A$2336,'Medical Examinations'!$F$2:$F$2336) -> No | H13: =_xlfn.XLOOKUP(A13,'Medical Examinations'!$A$2:$A$2336,'Medical Examinations'!$G$2:$G$2336) -> 0 | I13: =_xlfn.XLOOKUP(A13,'Medical Examinations'!$A$2:$A$2336,'Medical Examinations'!$H$2:$H$2336) -> Yes | J13: =VLOOKUP(A13,'Medical Examinations'!$A$2:$J$2336,9,FALSE) -> Obesity | K13: =VLOOKUP(A13,'Medical Examinations'!$A$2:$J$2336,10,FALSE) -> Diabetes | L13: =_xlfn.XLOOKUP(A13,'Hospitalisation Details'!$A$2:$A$2345,'Hospitalisation Details'!$J$2:$J$2345,"") -> 27-Oct-1965 | M13: =_xlfn.XLOOKUP(A13,'Hospitalisation Details'!$A$2:$A$2344,'Hospitalisation Details'!$F$2:$F$2344," ",0,1) -> 48675.52 | N13: =_xlfn.XLOOKUP(A13,'Hospitalisation Details'!$A$2:$A$2344,'Hospitalisation Details'!$G$2:$G$2344," ",0,1) -> tier - 1 | O13: =_xlfn.XLOOKUP(A13,'Hospitalisation Details'!$A$2:$A$2344,'Hospitalisation Details'!$H$2:$H$2344," ",0,1) -> tier - 2 | P13: =_xlfn.XLOOKUP(A13,'Hospitalisation Details'!$A$2:$A$2344,'Hospitalisation Details'!$I$2:$I$2344," ",0,1) -> R1013 | Q13: =_xlfn.XLOOKUP(A13,'Hospitalisation Details'!$A$2:$A$2344,'Hospitalisation Details'!$K$2:$K$2344," ",0,1) -> 57
... A2336: Id2335 | B2336: =VLOOKUP(Healthcare!A2336,'Customer Names'!A2336:E4670,4,FALSE) -> Aaron K | C2336: =_xlfn.XLOOKUP(A2336,'Medical Examinations'!$A$2:$A$2336,'Medical Examinations'!$B$2:$B$2336,"NA",0,1) -> 17.58 | D2336: =_xlfn.XLOOKUP(A2336,'Medical Examinations'!$A$2:$A$2336,'Medical Examinations'!$C$2:$C$2336) -> 4.51 | E2336: =_xlfn.XLOOKUP(A2336,'Medical Examinations'!$A$2:$A$2336,'Medical Examinations'!$D$2:$D$2336) -> No | F2336: =_xlfn.XLOOKUP(A2336,'Medical Examinations'!$A$2:$A$2336,'Medical Examinations'!$E$2:$E$2336) -> No | G2336: =_xlfn.XLOOKUP(A2336,'Medical Examinations'!$A$2:$A$2336,'Medical Examinations'!$F$2:$F$2336) -> No | H2336: =_xlfn.XLOOKUP(A2336,'Medical Examinations'!$A$2:$A$2336,'Medical Examinations'!$G$2:$G$2336) -> 1 | I2336: =_xlfn.XLOOKUP(A2336,'Medical Examinations'!$A$2:$A$2336,'Medical Examinations'!$H$2:$H$2336) -> No | J2336: =VLOOKUP(A2336,'Medical Examinations'!$A$2:$J$2336,9,FALSE) -> Underweight | K2336: =VLOOKUP(A2336,'Medical Examinations'!$A$2:$J$2336,10,FALSE) -> Normal | L2336: =_xlfn.XLOOKUP(A2336,'Hospitalisation Details'!$A$2:$A$2345,'Hospitalisation Details'!$J$2:$J$2345,"") -> 9-Jul-1992 | M2336: =_xlfn.XLOOKUP(A2336,'Hospitalisation Details'!$A$2:$A$2344,'Hospitalisation Details'!$F$2:$F$2344," ",0,1) -> 563.84 | N2336: =_xlfn.XLOOKUP(A2336,'Hospitalisation Details'!$A$2:$A$2344,'Hospitalisation Details'!$G$2:$G$2344," ",0,1) -> tier - 2 | O2336: =_xlfn.XLOOKUP(A2336,'Hospitalisation Details'!$A$2:$A$2344,'Hospitalisation Details'!$H$2:$H$2344," ",0,1) -> tier - 3 | P2336: =_xlfn.XLOOKUP(A2336,'Hospitalisation Details'!$A$2:$A$2344,'Hospitalisation Details'!$I$2:$I$2344," ",0,1) -> R1013 | Q2336: =_xlfn.XLOOKUP(A2336,'Hospitalisation Details'!$A$2:$A$2344,'Hospitalisation Details'!$K$2:$K$2344," ",0,1) -> 30

Sheet Dashboard
A1: HEALTHCARE ANALYSIS DASHBOARD
F4: Main analysis charts

Sheet Age vs Healthcare Charges.
A1: Age | B1: charges
A2: {=Healthcare!Q2:Q2336} -> 54 | B2: {=Healthcare!M2:M2336} -> 63770.43
A3: 46 | B3: 62592.87
A4: 52 | B4: 60021.4
A5: 32 | B5: 58571.07
A6: 33 | B6: 55135.4
A7: 60 | B7: 52590.83
A8: 28 | B8: 51194.56
A9: 64 | B9: 49577.66
A10: 59 | B10: 48970.25
A11: 44 | B11: 48885.14
A12: 63 | B12: 48824.45
A13: 57 | B13: 48675.52
A14: 60 | B14: 48673.56
... A2336: 30 | B2336: 563.84

Sheet Age vs BMIvs HBA1C
A1: Age | B1: BMI | D1: Age | E1: HBA1C
A2: {=Healthcare!Q2:Q2336} -> 54 | B2: {=Healthcare!C2:C2336} -> 47.41 | D2: {=Healthcare!Q2:Q2336} -> 54 | E2: {=Healthcare!D2:D2336} -> 7.47
A3: 46 | B3: 30.36 | D3: 46 | E3: 5.77
A4: 52 | B4: 34.485 | D4: 52 | E4: 11.87
A5: 32 | B5: 38.095 | D5: 32 | E5: 6.05
A6: 33 | B6: 35.53 | D6: 33 | E6: 5.45
A7: 60 | B7: 32.8 | D7: 60 | E7: 6.59
A8: 28 | B8: 36.4 | D8: 28 | E8: 6.07
A9: 64 | B9: 36.96 | D9: 64 | E9: 7.93
A10: 59 | B10: 41.14 | D10: 59 | E10: 9.58
A11: 44 | B11: 38.06 | D11: 44 | E11: 10.79
A12: 63 | B12: 37.7 | D12: 63 | E12: 5.96
A13: 57 | B13: 42.13 | D13: 57 | E13: 11.9
A14: 60 | B14: 40.92 | D14: 60 | E14: 8.41
... A17: 60 | B17: 39.9 | D17: 60 | E17: 11.32
A18: 64 | B18: 33.8 | D18: 64 | E18: 7.67 | H18: Age and BMI show a very weak linear relationship, as indicated by the R² value of 0.0027. The scatter plot shows that BMI varies considerably across different age groups.
A19: 59 | B19: 36.765 | D19: 59 | E19: 7.29
A20: 58 | B20: 36.955 | D20: 58 | E20: 4.72
A21: 51 | B21: 42.9 | D21: 51 | E21: 11.41
A22: 61 | B22: 36.3 | D22: 61 | E22: 11.5
A23: 63 | B23: 32.2 | D23: 63 | E23: 6.22
A24: 64 | B24: 31.3 | D24: 64 | E24: 11.38
A25: 52 | B25: 41.8 | D25: 52 | E25: 7.89
A26: 63 | B26: 35.09 | D26: 63 | E26: 4.38
A27: 64 | B27: 33.88 | D27: 64 | E27: 7.01
A28: 62 | B28: 30.875 | D28: 62 | E28: 11.88
A29: 53 | B29: 36.86 | D29: 53 | E29: 5.19
A30: 61 | B30: 35.86 | D30: 61 | E30: 6.74
... A38: 48 | B38: 40.565 | D38: 48 | E38: 7.37
A39: 60 | B39: 32.45 | D39: 60 | E39: 11.91 | H39: Age and HBA1C show a relatively stronger linear association than Age and BMI. The R² value of 0.212 indicates that the linear relationship with age explains about 21.2% of the variation in HBA1C in this dataset.
A40: 51 | B40: 34.96 | D40: 51 | E40: 6.52
A41: 29 | B41: 35.5 | D41: 29 | E41: 5.14
A42: 22 | B42: 52.58 | D42: 22 | E42: 4.19
A43: 55 | B43: 35.2 | D43: 55 | E43: 11.68
A44: 51 | B44: 38.06 | D44: 51 | E44: 6.98
A45: 54 | B45: 34.21 | D45: 54 | E45: 8.34
A46: 48 | B46: 38.94 | D46: 48 | E46: 8.49
A47: 34 | B47: 30.21 | D47: 34 | E47: 5.34
A48: 56 | B48: 33.63 | D48: 56 | E48: 4.43
A49: 42 | B49: 40.37 | D49: 42 | E49: 4.47
...

Sheet Average Healthcare Charges by H
A3: Average of charges
B4: tier - 1 | C4: tier - 2 | D4: tier - 3 | E4: Grand Total
A5: R1011 | B5: 33081.374 | C5: 18997.281 | D5: 9250.3618 | E5: 19466.246
A6: R1012 | B6: 26111.458 | C6: 10334.279 | D6: 10179.942 | E6: 12016.474
A7: R1013 | B7: 31328.102 | C7: 8439.2844 | D7: 6890.7568 | E7: 10514.94
A8: R1014 | B8: 13891.86 | C8: 2395.17 | D8: 16950.485 | E8: 13478.057
A9: R1015 | B9: 21523.52 | C9: 15675.543 | D9: 7570.755 | E9: 13948.61
A10: R1016 | B10: 39868.616 | C10: 16075.963 | D10: 8133.0084 | E10: 13589.263
A11: R1017 | B11: 34070.596 | C11: 11365.622 | D11: 8667.3662 | E11: 14806.108
A12: R1018 | B12: 33475.82 | C12: 10139.553 | D12: 12570.97 | E12: 13272.787
A13: R1019 | B13: 27621.61 | C13: 8116.72 | D13: 12706.976 | E13: 13633.143
A14: R1020 | C14: 6760.5433 | D14: 11716.453 | E14: 9238.4983
A15: R1021 | C15: 7668.1787 | D15: 11518.786 | E15: 8933.3781
A16: R1022 | C16: 10102.027 | D16: 11637.812 | E16: 10650.521
A17: R1023 | B17: 18261.757 | C17: 13457.095 | D17: 12785.637 | E17: 13786.149
A18: R1024 | B18: 32732.187 | C18: 10174.346 | D18: 13360.979 | E18: 12865.149
A19: R1025 | C19: 6886.0368 | D19: 10510.314 | E19: 8788.7823
A20: R1026 | B20: 18709.798 | C20: 11919.608 | D20: 12296.78 | E20: 12489.921
A21: Unknown | B21: 20996.53 | E21: 20996.53
A22: Grand Total | B22: 30129.199 | C22: 11865.269 | D22: 9462.2693 | E22: 13529.918

Sheet Average Healthcare Charges by W
A3: Average of charges | B3: Column Labels
A4: Row Labels | B4: Diabetes | C4: Normal | D4: Prediabetes | E4: Grand Total
A5: Normal Weight | B5: 12447.613 | C5: 7938.5057 | D5: 10492.131 | E5: 9851.9225
A6: Obesity | B6: 19347.657 | C6: 15188.437 | D6: 15353.902 | E6: 16661.463
A7: Overweight | B7: 14269.014 | C7: 10327.157 | D7: 9737.9402 | E7: 11435.413
A8: Underweight | B8: 7442.9649 | C8: 6911.0056 | D8: 5647.7483 | E8: 6899.3175
A9: Grand Total | B9: 16120.287 | C9: 12090.723 | D9: 12532.263 | E9: 13529.918

Sheet Transplants vs Major Surgeries 
A3: Row Labels | B3: Sum of NumberOfMajorSurgeries | C3: Average of HBA1C
A4: No | B4: 1417 | C4: 6.6704427
A5: Yes | B5: 162 | C5: 5.1876389
A6: Grand Total | B6: 1579 | C6: 6.5789979

Sheet Cancer History Distribution by 
A3: Count of Customer ID | B3: Column Labels
A4: Row Labels | B4: No | C4: Yes | D4: Grand Total
A5: No | B5: 1540 | C5: 307 | D5: 1847
A6: Yes | B6: 404 | C6: 84 | D6: 488
A7: Grand Total | B7: 1944 | C7: 391 | D7: 2335
